<mujoco model="anymal">
    <compiler angle="radian"  meshdir="../meshes/"/>
    <size njmax="500" nconmax="100" />
    <option integrator="Euler" timestep="0.01"/>    
<worldbody>
        <geom size="0.2655 0.135 0.12" pos="0 0 0.08" type="box" rgba="0.7 0.7 0.7 1" />
        <geom size="0.05 0.05" pos="0.227 0.116 0" quat="0.707107 0 0.707107 0" type="cylinder" rgba="0.7 0.7 0.7 1" />
        <geom size="0.05 0.05" pos="0.227 -0.116 0" quat="0.707107 0 0.707107 0" type="cylinder" rgba="0.7 0.7 0.7 1" />
        <geom size="0.05 0.05" pos="-0.227 0.116 0" quat="0.707107 0 0.707107 0" type="cylinder" rgba="0.7 0.7 0.7 1" />
        <geom size="0.05 0.05" pos="-0.227 -0.116 0" quat="0.707107 0 0.707107 0" type="cylinder" rgba="0.7 0.7 0.7 1" />
        <geom size="0.05 0.05 0.035" pos="0.2155 0 -0.09" type="box" rgba="0.7 0.7 0.7 1" />
        <geom size="0.05 0.05 0.035" pos="-0.2155 0 -0.09" type="box" rgba="0.7 0.7 0.7 1" />
        <geom size="0.2655 0.01 0.035" pos="0 0 -0.09" type="box" rgba="0.7 0.7 0.7 1" />
        <body name="LF_HIP" pos="0.277 0.116 0">
            <inertial pos="0.0645163 -0.0037871 -0.000152184" quat="0.996866 0.0379822 0.0252009 -0.0646548" mass="1.42462" diaginertia="0.00243341 0.00230249 0.00197758" />
            <joint name="LF_HAA" pos="0 0 0" axis="1 0 0" limited="true" range="-9.42 9.42" />
            <geom size="0.08 0.05" pos="0.0635 -0.009 0" quat="0.707107 0.707107 0 0" type="cylinder" rgba="0.7 0.7 0.7 1" />
            <geom size="0.045 0.015" pos="0.0635 -0.074 0" quat="0.707107 0.707107 0 0" type="cylinder" rgba="0.7 0.7 0.7 1" />
            <body name="LF_THIGH" pos="0.0635 0.041 0">
                <inertial pos="-0.00389797 0.0542266 -0.214583" quat="0.74395 -0.0633414 0.0362707 0.664237" mass="1.63498" diaginertia="0.0122697 0.0120427 0.00228302" />
                <joint name="LF_HFE" pos="0 0 0" axis="0 1 0" limited="true" range="-9.42 9.42" />
                <geom size="0.04 0.02 0.125" pos="0 0.035 -0.125" quat="0.997373 0.0724365 0 0" type="box" rgba="0.7 0.7 0.7 1" />
                <geom size="0.06 0.06" pos="0 0.069 -0.25" quat="0.707107 0.707107 0 0" type="cylinder" rgba="0.7 0.7 0.7 1" />
                <geom size="0.066 0.06" pos="0 -0.005 0" quat="0.654029 0.75647 0 0" type="cylinder" rgba="0.7 0.7 0.7 1" />
                <body name="LF_SHANK" pos="0 0.109 -0.25">
                    <inertial pos="0.0696396 -0.0132494 -0.150905" quat="0.677954 -0.0950614 -0.0578104 0.726636" mass="0.472163" diaginertia="0.0116034 0.0110666 0.000723761" />
                    <joint name="LF_KFE" pos="0 0 0" axis="0 1 0" limited="true" range="-9.42 9.42" />
                    <geom size="0.04 0.035 0.065" pos="0.065 -0.015 0.01" quat="0.707107 0 0.707107 0" type="box" rgba="0.7 0.7 0.7 1" />
                    <geom size="0.015 0.160625" pos="0.1 -0.02 -0.160625" type="cylinder" rgba="0.7 0.7 0.7 1" />
                    <geom size="0.031" pos="0.1 -0.02 -0.298" />
                </body>
            </body>
        </body>
        <body name="RF_HIP" pos="0.277 -0.116 0">
            <inertial pos="0.0645163 0.0037871 -0.000152184" quat="0.996866 -0.0379822 0.0252009 0.0646548" mass="1.42462" diaginertia="0.00243341 0.00230249 0.00197758" />
            <joint name="RF_HAA" pos="0 0 0" axis="1 0 0" limited="true" range="-9.42 9.42" />
            <geom size="0.08 0.05" pos="0.0635 0.009 0" quat="0.707107 0.707107 0 0" type="cylinder" rgba="0.7 0.7 0.7 1" />
            <geom size="0.045 0.015" pos="0.0635 0.074 0" quat="0.707107 0.707107 0 0" type="cylinder" rgba="0.7 0.7 0.7 1" />
            <body name="RF_THIGH" pos="0.0635 -0.041 0">
                <inertial pos="-0.00389797 -0.0542266 -0.214583" quat="0.664237 0.0362707 -0.0633414 0.74395" mass="1.63498" diaginertia="0.0122697 0.0120427 0.00228302" />
                <joint name="RF_HFE" pos="0 0 0" axis="0 1 0" limited="true" range="-9.42 9.42" />
                <geom size="0.04 0.02 0.125" pos="0 -0.035 -0.125" quat="0.997373 -0.0724365 0 0" type="box" rgba="0.7 0.7 0.7 1" />
                <geom size="0.06 0.06" pos="0 -0.069 -0.25" quat="0.707107 0.707107 0 0" type="cylinder" rgba="0.7 0.7 0.7 1" />
                <geom size="0.066 0.06" pos="0 0.005 0" quat="0.654029 -0.75647 0 0" type="cylinder" rgba="0.7 0.7 0.7 1" />
                <body name="RF_SHANK" pos="0 -0.109 -0.25">
                    <inertial pos="0.0696396 0.0132494 -0.150905" quat="0.726636 -0.0578104 -0.0950614 0.677954" mass="0.472163" diaginertia="0.0116034 0.0110666 0.000723761" />
                    <joint name="RF_KFE" pos="0 0 0" axis="0 1 0" limited="true" range="-9.42 9.42" />
                    <geom size="0.04 0.035 0.065" pos="0.065 0.015 0.01" quat="0.707107 0 0.707107 0" type="box" rgba="0.7 0.7 0.7 1" />
                    <geom size="0.015 0.160625" pos="0.1 0.02 -0.160625" type="cylinder" rgba="0.7 0.7 0.7 1" />
                    <geom size="0.031" pos="0.1 0.02 -0.298" />
                </body>
            </body>
        </body>
        <body name="LH_HIP" pos="-0.277 0.116 0">
            <inertial pos="-0.0645163 -0.0037871 -0.000152184" quat="0.996866 0.0379822 -0.0252009 0.0646548" mass="1.42462" diaginertia="0.00243341 0.00230249 0.00197758" />
            <joint name="LH_HAA" pos="0 0 0" axis="1 0 0" limited="true" range="-9.42 9.42" />
            <geom size="0.08 0.05" pos="-0.0635 -0.009 0" quat="0.707107 -0.707107 0 0" type="cylinder" rgba="0.7 0.7 0.7 1" />
            <geom size="0.045 0.015" pos="-0.0635 -0.074 0" quat="0.707107 -0.707107 0 0" type="cylinder" rgba="0.7 0.7 0.7 1" />
            <body name="LH_THIGH" pos="-0.0635 0.041 0">
                <inertial pos="0.00389797 0.0542266 -0.214583" quat="0.664237 -0.0362707 0.0633414 0.74395" mass="1.63498" diaginertia="0.0122697 0.0120427 0.00228302" />
                <joint name="LH_HFE" pos="0 0 0" axis="0 1 0" limited="true" range="-9.42 9.42" />
                <geom size="0.04 0.02 0.125" pos="0 0.035 -0.125" quat="0.997373 0.0724365 0 0" type="box" rgba="0.7 0.7 0.7 1" />
                <geom size="0.06 0.06" pos="0 0.069 -0.25" quat="0.707107 0.707107 0 0" type="cylinder" rgba="0.7 0.7 0.7 1" />
                <geom size="0.066 0.06" pos="0 -0.005 0" quat="0.654029 0.75647 0 0" type="cylinder" rgba="0.7 0.7 0.7 1" />
                <body name="LH_SHANK" pos="0 0.109 -0.25">
                    <inertial pos="-0.0696396 -0.0132494 -0.150905" quat="0.726636 0.0578104 0.0950615 0.677954" mass="0.472163" diaginertia="0.0116034 0.0110666 0.000723761" />
                    <joint name="LH_KFE" pos="0 0 0" axis="0 1 0" limited="true" range="-9.42 9.42" />
                    <geom size="0.04 0.035 0.065" pos="-0.065 -0.015 0.01" quat="0.707107 0 0.707107 0" type="box" rgba="0.7 0.7 0.7 1" />
                    <geom size="0.015 0.160625" pos="-0.1 -0.02 -0.160625" type="cylinder" rgba="0.7 0.7 0.7 1" />
                    <geom size="0.031" pos="-0.1 -0.02 -0.298" />
                </body>
            </body>
        </body>
        <body name="RH_HIP" pos="-0.277 -0.116 0">
            <inertial pos="-0.0645163 0.0037871 -0.000152184" quat="0.996866 -0.0379822 -0.0252009 -0.0646548" mass="1.42462" diaginertia="0.00243341 0.00230249 0.00197758" />
            <joint name="RH_HAA" pos="0 0 0" axis="1 0 0" limited="true" range="-9.42 9.42" />
            <geom size="0.08 0.05" pos="-0.0635 0.009 0" quat="0.707107 -0.707107 0 0" type="cylinder" rgba="0.7 0.7 0.7 1" />
            <geom size="0.045 0.015" pos="-0.0635 0.074 0" quat="0.707107 -0.707107 0 0" type="cylinder" rgba="0.7 0.7 0.7 1" />
            <body name="RH_THIGH" pos="-0.0635 -0.041 0">
                <inertial pos="0.00389797 -0.0542266 -0.214583" quat="0.74395 0.0633414 -0.0362707 0.664237" mass="1.63498" diaginertia="0.0122697 0.0120427 0.00228302" />
                <joint name="RH_HFE" pos="0 0 0" axis="0 1 0" limited="true" range="-9.42 9.42" />
                <geom size="0.04 0.02 0.125" pos="0 -0.035 -0.125" quat="0.997373 -0.0724365 0 0" type="box" rgba="0.7 0.7 0.7 1" />
                <geom size="0.06 0.06" pos="0 -0.069 -0.25" quat="0.707107 0.707107 0 0" type="cylinder" rgba="0.7 0.7 0.7 1" />
                <geom size="0.066 0.06" pos="0 0.005 0" quat="0.654029 -0.75647 0 0" type="cylinder" rgba="0.7 0.7 0.7 1" />
                <body name="RH_SHANK" pos="0 -0.109 -0.25">
                    <inertial pos="-0.0696396 0.0132494 -0.150905" quat="0.677954 0.0950614 0.0578104 0.726636" mass="0.472163" diaginertia="0.0116034 0.0110666 0.000723761" />
                    <joint name="RH_KFE" pos="0 0 0" axis="0 1 0" limited="true" range="-9.42 9.42" />
                    <geom size="0.04 0.035 0.065" pos="-0.065 0.015 0.01" quat="0.707107 0 0.707107 0" type="box" rgba="0.7 0.7 0.7 1" />
                    <geom size="0.015 0.160625" pos="-0.1 0.02 -0.160625" type="cylinder" rgba="0.7 0.7 0.7 1" />
                    <geom size="0.031" pos="-0.1 0.02 -0.298" />
                </body>
            </body>
        </body>
    </worldbody>

    <actuator>
      <motor ctrllimited="true" ctrlrange="-1.0 1.0" joint="LF_HAA" gear="15000"/>
      <motor ctrllimited="true" ctrlrange="-1.0 1.0" joint="LF_HFE" gear="150"/>
      <motor ctrllimited="true" ctrlrange="-1.0 1.0" joint="LF_KFE" gear="150"/>
      <motor ctrllimited="true" ctrlrange="-1.0 1.0" joint="RF_HAA" gear="150"/>
      <motor ctrllimited="true" ctrlrange="-1.0 1.0" joint="RF_HFE" gear="150"/>
      <motor ctrllimited="true" ctrlrange="-1.0 1.0" joint="RF_KFE" gear="150"/>
      <motor ctrllimited="true" ctrlrange="-1.0 1.0" joint="LH_HAA" gear="150"/>
      <motor ctrllimited="true" ctrlrange="-1.0 1.0" joint="LH_HFE" gear="150"/>    
      <motor ctrllimited="true" ctrlrange="-1.0 1.0" joint="LH_KFE" gear="150"/>
      <motor ctrllimited="true" ctrlrange="-1.0 1.0" joint="RH_HAA" gear="150"/>
      <motor ctrllimited="true" ctrlrange="-1.0 1.0" joint="RH_HFE" gear="150"/>    
      <motor ctrllimited="true" ctrlrange="-1.0 1.0" joint="RH_KFE" gear="150"/> 
    </actuator>
</mujoco>
