<?xml version="1.0" encoding="utf-8"?>
<mujoco>
    <compiler angle="radian" coordinate="local" meshdir="../stls/hand" texturedir="../textures"></compiler>
    <option timestep="0.01" iterations="20" apirate="200">
        <flag warmstart="enable"></flag>
    </option>

    <include file="shared.xml"></include>

    <asset>
        <texture name="grid" type="2d" builtin="checker" rgb1=".1 .2 .3" rgb2=".2 .3 .4" width="300" height="300" mark="edge" markrgb=".2 .3 .4"/>
        <material name="grid" texture="grid" texrepeat="1 1" texuniform="true" reflectance=".2"/>
        <material name="self" rgba=".7 .5 .3 1"/>
        <material name="self_default" rgba=".7 .5 .3 1"/>
        <material name="self_highlight" rgba="0 .5 .3 1"/>
        <material name="effector" rgba=".7 .4 .2 1"/>
        <material name="effector_default" rgba=".7 .4 .2 1"/>
        <material name="effector_highlight" rgba="0 .5 .3 1"/>
        <material name="decoration" rgba=".3 .5 .7 1"/>
        <material name="eye" rgba="0 .2 1 1"/>
        <material name="target" rgba=".6 .3 .3 1"/>
        <material name="target_default" rgba=".6 .3 .3 1"/>
        <material name="target_highlight" rgba=".6 .3 .3 .4"/>
    </asset>


    <asset>
        <include file="shared_asset.xml"></include>

        <material name="material:object" specular="0" shininess="0.5" reflectance="0.0" rgba="0.46 0.81 0.88 1.0"></material>
        <material name="material:target" specular="0" shininess="0.5" reflectance="0.0" rgba="0.46 0.81 0.88 0.5"></material>
    </asset>

    <worldbody>
        <geom name="floor0" pos="1 1 -0.2" size="1 1 1" type="plane" condim="3" material="floor_mat"></geom>
        <body name="floor0" pos="1 1 0"></body>
        <include file="robot.xml"></include>
        <camera mode="targetbody"></camera>

        <body name="spinner" pos="1 0.82 0.1722" quat="0.707107 0.707107 0 0">
            <joint name="hinge" axis="0 -1 0" range="-50 50" frictionloss=".01" damping=".35" limited="false"/>
            <geom name="cap2" type="capsule" size=".015 .09" material="self" pos="-.0 0 0"/>
            <geom name="spinner_decoration" type="cylinder" fromto="0 -.02 0 0 .02 0" size=".005" material="decoration"/>
        </body>

        <light directional="true" ambient="0.2 0.2 0.2" diffuse="0.8 0.8 0.8" specular="0.3 0.3 0.3" castshadow="false" pos="0 1 4" dir="0 0 -1" name="light0"></light>
    </worldbody>
</mujoco>
