<mujoco model="planar point mass">
    <visual>
        <quality shadowsize="2048" />
        <headlight ambient="0.4 0.4 0.4" diffuse="0.8 0.8 0.8" specular="0.1 0.1 0.1" />
    </visual>

    <default class="main">
        <general ctrllimited="true" ctrlrange="-1 1" />
    </default>

    <default class="object">
        <geom material="self"/>
    </default>

    <asset>
        <texture type="skybox" name="skybox" builtin="gradient" mark="random" rgb1="0.4 0.6 0.8" rgb2="0 0 0" markrgb="1 1 1" width="800" height="4800" />
        <texture type="2d" name="grid" builtin="checker" mark="edge" rgb1="0.1 0.2 0.3" rgb2="0.2 0.3 0.4" markrgb="0.2 0.3 0.4" width="300" height="300" />
        <material name="grid" texture="grid" texuniform="true" reflectance="0.2" />
        <material name="self" rgba="0.7 0.5 0.3 1" />
        <material name="self_default" rgba="0.7 0.5 0.3 1" />
        <material name="self_highlight" rgba="0 0.5 0.3 1" />
        <material name="effector" rgba="0.7 0.4 0.2 1" />
        <material name="effector_default" rgba="0.7 0.4 0.2 1" />
        <material name="effector_highlight" rgba="0 0.5 0.3 1" />
        <material name="decoration" rgba="0.3 0.5 0.7 1" />
        <material name="eye" rgba="0 0.2 1 1" />
        <material name="target" rgba="0.6 0.3 0.3 1" />
        <material name="target_default" rgba="0.6 0.3 0.3 1" />
        <material name="target_highlight" rgba="0.6 0.3 0.3 0.4" />
    </asset>

    <option timestep="0.01"> </option>
    <default class="finger">
        <site type="ellipsoid" size=".025 .03 .025" rgba=".5 .5 .5 .3" group="3"/>
    </default>

    <worldbody>
        <geom name="ground" size="0.61 0.61 0.1" pos="-0.0 0 0.0" type="plane" rgba="0.25 0.5 1 1"/>
        <geom name="wall_x" size="0.05 0.61 0.02" pos="-0.61 0 0.05" quat="0.707107 0 0.707107 0" type="plane" rgba="0.5 0.15 0 1"/>
        <geom name="wall_y" size="0.61 0.05 0.02" pos="0 -0.61 0.05" quat="0.707107 -0.707107 0 0" type="plane" rgba="0.5 0.15 0 1"/>
        <geom name="wall_neg_x" size="0.05 0.61 0.02" pos="0.61 0 0.05" quat="0.707107 0 -0.707107 0" type="plane" rgba="0.5 0.15 0 1"/>
        <geom name="wall_neg_y" size="0.61 0.05 0.02" pos="0 0.61 0.05" quat="0.707107 0.707107 0 0" type="plane" rgba="0.5 0.15 0 1"/>
        <camera name="fixed" pos="0 0 0.75" />
        <light name="light" pos="0 0 1" dir="0 0 -1" />


        <body name="pointmass" pos="-.0 .0 .042">
            <camera name="cam0" pos="0 -0.3 0.3" xyaxes="1 0 0 0 0.7 0.7"/>
            <joint name="root_x" type="slide"  pos="0 0 0" axis="1 0 0" damping="3" frictionloss=".01"/>
            <joint name="root_y" type="slide"  pos="0 0 0" axis="0 1 0" damping="3" frictionloss=".01"/>
            <geom name="pointmass" type="sphere" size=".042" material="self" mass=".6" condim="4"  group="2" solimp="0.9 0.95 0.001" solref="0.02 1"/>
        </body>

        <body name="pointmass2" pos="-.0 .0 .042">
            <camera name="cam1" pos="0 -0.3 0.3" xyaxes="1 0 0 0 0.7 0.7"/>
            <joint name="root_x2" type="slide"  pos="0 0 0" axis="1 0 0" damping="3" frictionloss=".01"/>
            <joint name="root_y2" type="slide"  pos="0 0 0" axis="0 1 0" damping="3" frictionloss=".01"/>
            <geom name="pointmass2" type="sphere" size=".042" material="self" mass=".6" condim="4"  group="2" solimp="0.9 0.95 0.001" solref="0.02 1"/>
        </body>

    </worldbody>

    <tendon>
        <fixed name="t1">
            <joint joint="root_x" coef="1"/>
            <joint joint="root_y" coef="0"/>
        </fixed>
        <fixed name="t2">
            <joint joint="root_x" coef="0"/>
            <joint joint="root_y" coef="1"/>
        </fixed>
    </tendon>

    <contact>
        <exclude body1="pointmass" body2="world"/>
        <exclude body1="pointmass2" body2="world"/>
    </contact>


</mujoco>
