<!--NOTE:-->
<!--COMPARE AT 30 and 100 SAMPLES with cov reg as 0.5 with 0.9 importance lambda 0.001-->
<!--0.9 importance and 1 cov reg fro 100 samples-->

<mujoco model="planar_point_mass_1D">
    <compiler angle="radian"></compiler>

    <visual>
        <quality shadowsize="2048" />
        <headlight ambient="0.4 0.4 0.4" diffuse="0.8 0.8 0.8" specular="0.1 0.1 0.1" />
    </visual>

    <option timestep="0.01" integrator="RK4">
        <flag contact="enable" energy="enable" gravity="enable"/>
    </option>

    <asset>
        <texture type="skybox" name="skybox" builtin="gradient" mark="random" rgb1="0.4 0.6 0.8" rgb2="0 0 0" markrgb="1 1 1" width="800" height="4800" />
        <texture type="2d" name="grid" builtin="checker" mark="edge" rgb1="0.1 0.2 0.3" rgb2="0.2 0.3 0.4" markrgb="0.2 0.3 0.4" width="300" height="300" />
    </asset>

    <worldbody>
        <geom name="ground" size="4 4 0.1" pos="-0.0 0 0.0" type="plane" rgba=".123 .140 .28 1"/>
        <geom name="wall_x" size="0.02 4 0.02" pos="-4 0 0.02" quat="0.707107 0 0.707107 0" type="plane" rgba=".250 .126 .2 1"/>
        <geom name="wall_y" size="4 0.02 0.02" pos="0 -4 0.02" quat="0.707107 -0.707107 0 0" type="plane" rgba=".250 .126 .2 1" />
        <geom name="wall_neg_x" size="0.02 4 0.02" pos="4 0 0.02" quat="0.707107 0 -0.707107 0" type="plane" rgba=".250 .126 .2 1"/>
        <geom name="wall_neg_y" size="4 0.02 0.02" pos="0 4 0.02" quat="0.707107 0.707107 0 0" type="plane" rgba=".250 .126 .2 1"/>
        <camera name="fixed" pos="0 0 0.75" />
        <light name="light" pos="0 0 1" dir="0 0 -1" />

        <body name="box0" pos=".0 0 .111">
            <joint name="box0_x" type="slide" axis="1 0 0" ref="0" solreflimit=".08 1" damping="5e-1"/>
<!--            <joint name="box0_y" type="slide" axis="0 1 0" ref="0" solreflimit=".08 1" damping="5e-1"/>-->
            <geom  name="box0" type="sphere" size="0.1 0.11 0.1"  mass="1" rgba="0.7 0.1 0.3 1"/>
        </body>

        <body name="box1" pos=".0 0 .111">
            <joint name="box1_x" type="slide" axis="1 0 0" ref="0" solreflimit=".08 1" damping="5e-1"/>
<!--            <joint name="box1_y" type="slide" axis="0 1 0" ref="0" solreflimit=".08 1" damping="5e-1"/>-->
            <geom  name="box1" type="sphere" size="0.1 0.11 0.1"  mass="1" rgba="0.2 0.5 0.3 1"/>
        </body>
    </worldbody>

    <actuator>
        <general name="slider" joint="box0_x" gear="0.35 0 0 0 0 0" />
    </actuator>
</mujoco>
