<mujoco model="planar point mass">
    <visual>
        <quality shadowsize="2048" />
        <headlight ambient="0.4 0.4 0.4" diffuse="0.8 0.8 0.8" specular="0.1 0.1 0.1" />
    </visual>

    <default class="main">
        <geom friction=".7" solimp="0.9 0.97 0.001" solref=".01 1"/>
        <joint solimplimit="0 0.99 0.01" solreflimit=".005 1"/>
        <general ctrllimited="true" ctrlrange="-1 1" />
    </default>

    <default class="object">
        <geom material="self"/>
    </default>

    <asset>
        <texture type="skybox" name="skybox" builtin="gradient" mark="random" rgb1="0.4 0.6 0.8" rgb2="0 0 0" markrgb="1 1 1" width="800" height="4800" />
        <texture type="2d" name="grid" builtin="checker" mark="edge" rgb1="0.1 0.2 0.3" rgb2="0.2 0.3 0.4" markrgb="0.2 0.3 0.4" width="300" height="300" />
        <material name="grid" texture="grid" texuniform="true" reflectance="0.2" />
        <material name="self" rgba="0.7 0.5 0.3 1" />
        <material name="self_default" rgba="0.7 0.5 0.3 1" />
        <material name="self_highlight" rgba="0 0.5 0.3 1" />
        <material name="effector" rgba="0.7 0.4 0.2 1" />
        <material name="effector_default" rgba="0.7 0.4 0.2 1" />
        <material name="effector_highlight" rgba="0 0.5 0.3 1" />
        <material name="decoration" rgba="0.3 0.5 0.7 1" />
        <material name="eye" rgba="0 0.2 1 1" />
        <material name="target" rgba="0.6 0.3 0.3 1" />
        <material name="target_default" rgba="0.6 0.3 0.3 1" />
        <material name="target_highlight" rgba="0.6 0.3 0.3 0.4" />
    </asset>

    <option timestep="0.005"> </option>

    <worldbody>
        <geom name="ground" size="0.31 0.31 0.1" pos="-0.0 0 0.0" type="plane" />
        <geom name="wall_x" size="0.02 0.3 0.02" pos="-0.31 0 0.02" quat="0.707107 0 0.707107 0" type="plane" />
        <geom name="wall_y" size="0.3 0.02 0.02" pos="0 -0.31 0.02" quat="0.707107 -0.707107 0 0" type="plane" />
        <geom name="wall_neg_x" size="0.02 0.3 0.02" pos="0.31 0 0.02" quat="0.707107 0 -0.707107 0" type="plane" />
        <geom name="wall_neg_y" size="0.3 0.02 0.02" pos="0 0.31 0.02" quat="0.707107 0.707107 0 0" type="plane" />
        <camera name="fixed" pos="0 0 0.75" />
        <light name="light" pos="0 0 1" dir="0 0 -1" />
        <body pos="0 0 0.022" quat="0.707107 0.707107 0 0">
            <inertial pos="0 0 -0.0291932" mass="0.0591876" diaginertia="7.61519e-05 7.40747e-05 6.21876e-06" />
            <joint name="proximal" pos="0 0 0" axis="0 -1 0" ref="-1.5708" range="-130 -60" damping="0.25" />
            <geom name="proximal_decoration" size="0.024 0.02" quat="0.707107 0.707107 0 0" type="cylinder" material="decoration" />
            <geom name="proximal" size="0.015 0.05" pos="0 0 -0.05" type="capsule" material="self" />
            <body pos="0 0 -0.1">
                <inertial pos="0 0 -0.05" mass="0.0217147" diaginertia="2.14541e-05 2.14541e-05 6.9487e-07" />
                <joint name="distal" pos="0 0 0" axis="0 -1 0" range="-45 45" damping="0.3" />
                <geom name="distal" size="0.012 0.05" pos="0 0 -0.05" type="capsule" material="self" />
                <body pos="0 0 -0.1">
                    <inertial pos="0 0 -0.05" mass="0.00522761" diaginertia="4.73273e-06 4.73273e-06 4.18209e-08" />
                    <joint name="distal2" pos="0 0 0" axis="0 -1 0" range="-45 45" damping="0.4" />
                    <geom name="distal2" size="0.01 0.05" pos="0 0 -0.05" type="capsule" material="self"/>
                </body>
            </body>
        </body>
        <body name="pointmass" pos="-.0 .0 .022">
            <camera name="cam0" pos="0 -0.3 0.3" xyaxes="1 0 0 0 0.7 0.7"/>
            <joint name="root_x" type="slide"  pos="0 0 0" axis="1 0 0" damping="3"/>
            <joint name="root_y" type="slide"  pos="0 0 0" axis="0 1 0" damping="3"/>
            <geom name="pointmass" type="sphere" size=".022" material="self" mass=".6" condim="4"/>
        </body>

        <geom name="target" pos="-0.13 0 0.022" material="target" type="sphere" rgba="0.5 0 1 0.25"  size=".025" contype="0" conaffinity="0"/>
    </worldbody>

    <tendon>
        <fixed name="t1">
            <joint joint="root_x" coef="1"/>
            <joint joint="root_y" coef="0"/>
        </fixed>
        <fixed name="t2">
            <joint joint="root_x" coef="0"/>
            <joint joint="root_y" coef="1"/>
        </fixed>
    </tendon>

    <actuator>
        <general name="proximal" joint="proximal" gear="0.8 0 0 0 0 0" />
        <general name="distal" joint="distal" gear="0.8 0 0 0 0 0" />
        <general name="distal2" joint="distal2" gear="0.8 0 0 0 0 0" />
    </actuator>
</mujoco>
