<mujoco model="finger">

	<option timestep="0.01" cone="elliptic" iterations="200">

	</option>

	<default>
		<geom solimp="0 0.9 0.01" solref=".02 1"/>
		<joint type="hinge" axis="0 -1 0"/>
		<motor ctrllimited="false"/>
		<default class="finger">
			<joint damping=".01" limited="false"/>
			<motor ctrllimited="false"/>
			<site type="ellipsoid" size=".025 .03 .025" group="3"/>
		</default>
	</default>

	<worldbody>
		<light name="light" directional="true" diffuse=".6 .6 .6" pos="0 0 2" specular=".3 .3 .3"/>
		<geom name="ground" type="plane" pos="0 0 0" size=".6 .2 10"/>
		<camera name="cam0" pos="0 -1 .8" xyaxes="1 0 0 0 1 2"/>
		<camera name="cam1" pos="0 -1 .4" xyaxes="1 0 0 0 0 1" />

		<body name="proximal" pos="-.2 0 .4" childclass="finger">
			<geom name="proximal_decoration" type="cylinder" fromto="0 -.033 0 0 .033 0" size=".034"/>
			<joint name="proximal" range="-110 110" ref="-90"/>
			<geom name="proximal" type="capsule" size=".03" fromto="0 0 0 0 0 -.17"/>
			<body name="distal" pos="0 0 -.18" childclass="finger">
				<joint name="distal" range="-110 110"/>
				<geom name="distal" type="capsule" size=".028" fromto="0 0 0 0 0 -.16" contype="0" conaffinity="0"/>
				<geom name="fingertip" type="capsule" size=".03"  fromto="0 0 -.13 0 0 -.161"/>
				<site name="touchtop" pos=".01 0 -.17"/>
				<site name="touchbottom" pos="-.01 0 -.17"/>
			</body>
		</body>

		<body name="spinner" pos=".1 0 .4">
			<joint name="hinge" frictionloss="0" damping=".01"/>
			<geom name="cap1" type="capsule" size=".04 .09" pos=".02 0 0"/>
			<geom name="cap2" type="capsule" size=".04 .09" pos="-.02 0 0"/>
			<site name="tip" type="sphere"  size=".02" pos="0 0 .13"/>
			<geom name="spinner_decoration" type="cylinder" fromto="0 -.045 0 0 .045 0" size=".02"/>
		</body>

<!--		<site name="target" type="sphere" size=".03" pos="0 0 .4"/>-->
	</worldbody>

	<actuator>
		<motor name="proximal" joint="proximal" gear="1"/>
		<motor name="distal" joint="distal" gear="1"/>
		<motor name="hinge" joint="distal" gear="1"/>
	</actuator>

	<!-- All finger observations are functions of sensors. This is useful for finite-differencing. -->
	<sensor>
		<jointpos name="proximal" joint="proximal"/>
		<jointpos name="distal" joint="distal"/>
		<jointvel name="proximal_velocity" joint="proximal"/>
		<jointvel name="distal_velocity" joint="distal"/>
		<jointvel name="hinge_velocity" joint="hinge"/>
		<framepos name="tip" objtype="site" objname="tip"/>
<!--		<framepos name="target" objtype="site" objname="target"/>-->
		<framepos name="spinner" objtype="xbody" objname="spinner"/>
		<touch name="touchtop" site="touchtop"/>
		<touch name="touchbottom" site="touchbottom"/>
		<framepos name="touchtop_pos" objtype="site" objname="touchtop"/>
		<framepos name="touchbottom_pos" objtype="site" objname="touchbottom"/>
	</sensor>

</mujoco>

