<mujoco model="cartpole">

    <visual>
        <headlight ambient=".4 .4 .4" diffuse=".8 .8 .8" specular="0.1 0.1 0.1"/>
        <map znear=".01"/>
        <quality shadowsize="2048"/>
    </visual>

    <asset>
        <texture name="skybox" type="skybox" builtin="gradient" rgb1=".4 .6 .8" rgb2="0 0 0"
                 width="800" height="800" mark="random" markrgb="1 1 1"/>
    </asset>

    <asset>
        <texture name="grid" type="2d" builtin="checker" rgb1=".1 .2 .3" rgb2=".2 .3 .4" width="300" height="300" mark="edge" markrgb=".2 .3 .4"/>
        <material name="grid" texture="grid" texrepeat="1 1" texuniform="true" reflectance=".2"/>
        <material name="self" rgba=".7 .5 .3 1"/>
        <material name="self_default" rgba=".7 .5 .3 1"/>
        <material name="self_highlight" rgba="0 .5 .3 1"/>
        <material name="effector" rgba=".7 .4 .2 1"/>
        <material name="effector_default" rgba=".7 .4 .2 1"/>
        <material name="effector_highlight" rgba="0 .5 .3 1"/>
        <material name="decoration" rgba=".3 .5 .7 1"/>
        <material name="eye" rgba="0 .2 1 1"/>
        <material name="target" rgba=".6 .3 .3 1"/>
        <material name="target_default" rgba=".6 .3 .3 1"/>
        <material name="target_highlight" rgba=".6 .3 .3 .4"/>
    </asset>
    <option timestep="0.01" integrator="RK4">
        <flag contact="disable" energy="enable" gravity="enable"/>
    </option>

    <default>
        <default class="pole">
            <joint type="hinge" axis="0 1 0"  damping="2e-6"/>
            <geom type="capsule" fromto="0 0 0 0 0 1" size="0.045" material="self" mass=".1"/>
        </default>
        <default class="pole_2">
            <joint type="hinge" axis="0 1 0"  damping="2e-6"/>
            <geom type="capsule" fromto="0 0 0 0 0 1" size="0.045" material="self" mass=".1"/>
        </default>

    </default>


    <worldbody>
        <light name="light" pos="0 0 6"/>
        <camera name="fixed" pos="0 -4 1" zaxis="0 -1 0"/>
        <camera name="lookatcart" mode="targetbody" target="cart" pos="0 -2 2"/>
        <geom name="floor" pos="0 0 -.05" size="4 4 .2" type="plane" material="grid"/>
        <geom name="rail1" type="capsule" pos="0  .07 1" zaxis="1 0 0" size="0.02 4" material="decoration" />
        <geom name="rail2" type="capsule" pos="0 -.07 1" zaxis="1 0 0" size="0.02 4" material="decoration" />
        <body name="cart" pos="0 0 1">
            <joint name="slider" type="slide" limited="false" axis="1 0 0" range="-1.8 1.8" solreflimit=".08 1" damping="5e-4"/>
            <geom name="cart" type="box" size="0.2 0.15 0.1" material="self"  mass="1"/>
            <body name="pole_1" childclass="pole">
                <joint name="hinge_1"/>
                <geom name="pole_1"/>
            </body>
        </body>
    </worldbody>

    <actuator>
        <motor name="slide" joint="slider" gear="10" ctrllimited="true" ctrlrange="-1 1" />
    </actuator>

</mujoco>