<mujoco model="planar point mass">
    <compiler angle="radian" />
    <option timestep="0.01" cone="elliptic" iterations="200" />
    <size njmax="500" nconmax="100" />
    <visual>
        <quality shadowsize="2048" />
        <headlight ambient="0.4 0.4 0.4" diffuse="0.8 0.8 0.8" specular="0.1 0.1 0.1" />
    </visual>
    <default class="finger">
        <geom condim="4" solref="0.005 0.6" solimp="0 0.9 0.01 0.5 2" margin="0.001" />
        <site size="0.025 0.03 0.025" group="3" type="ellipsoid" rgba="0.5 0.5 0.5 0.3" />
        <general ctrllimited="true" ctrlrange="-1 1" />
    </default>
    <asset>
        <texture type="skybox" name="skybox" builtin="gradient" mark="random" rgb1="0.4 0.6 0.8" rgb2="0 0 0" markrgb="1 1 1" width="800" height="4800" />
        <texture type="2d" name="grid" builtin="checker" mark="edge" rgb1="0.1 0.2 0.3" rgb2="0.2 0.3 0.4" markrgb="0.2 0.3 0.4" width="300" height="300" />
        <material name="grid" texture="grid" texuniform="true" reflectance="0.2" />
        <material name="self" rgba="0.7 0.5 0.3 1" />
        <material name="self_default" rgba="0.7 0.5 0.3 1" />
        <material name="self_highlight" rgba="0 0.5 0.3 1" />
        <material name="effector" rgba="0.7 0.4 0.2 1" />
        <material name="effector_default" rgba="0.7 0.4 0.2 1" />
        <material name="effector_highlight" rgba="0 0.5 0.3 1" />
        <material name="decoration" rgba="0.3 0.5 0.7 1" />
        <material name="eye" rgba="0 0.2 1 1" />
        <material name="target" rgba="0.6 0.3 0.3 1" />
        <material name="target_default" rgba="0.6 0.3 0.3 1" />
        <material name="target_highlight" rgba="0.6 0.3 0.3 0.4" />
    </asset>
    <worldbody>
        <geom name="ground" size="0.61 0.61 0.1" type="plane" />
        <geom name="wall_x" size="0.05 0.61 0.02" pos="-0.61 0 0.05" quat="0.707107 0 0.707107 0" type="plane" />
        <geom name="wall_y" size="0.61 0.05 0.02" pos="0 -0.61 0.05" quat="0.707107 -0.707107 0 0" type="plane" />
        <geom name="wall_neg_x" size="0.05 0.61 0.02" pos="0.61 0 0.05" quat="0.707107 0 -0.707107 0" type="plane" />
        <geom name="wall_neg_y" size="0.61 0.05 0.02" pos="0 0.61 0.05" quat="0.707107 0.707107 0 0" type="plane" />
        <camera name="fixed" pos="0 0 0.75" />
        <light name="light" pos="0 0 1" dir="0 0 -1" />
        <body pos="0 0 0.035" quat="0.707107 0.707107 0 0">
            <inertial pos="0 0 -0.0596966" mass="0.805178" diaginertia="0.00338471 0.00336697 0.000410748" />
            <joint name="proximal" pos="0 0 0" axis="0 -1 0" ref="-90" range="-150 -80" damping="0.05" />
            <geom name="proximal_decoration" size="0.034 0.033" quat="0.707107 0.707107 0 0" type="cylinder" material="decoration" />
            <geom name="proximal" size="0.03 0.085" pos="0 0 -0.085" type="capsule" material="self" />
            <body name="distal" childclass="finger" pos="0 0 -0.18">
                <inertial pos="0 0 -0.08" mass="0.463046" diaginertia="0.00145458 0.00145458 0.000181514" />
                <joint name="distal" pos="0 0 0" axis="0 -1 0" range="-50 50" damping="0.05" />
                <geom name="distal" size="0.028 0.08" pos="0 0 -0.08" type="capsule" material="self" />
                <body name="distal2" childclass="finger" pos="0 0 -0.18">
                    <inertial pos="0 0 -0.097776" mass="0.635519" diaginertia="0.00208601 0.00208601 0.000259127" />
                    <joint name="distal2" pos="0 0 0" axis="0 -1 0" range="-50 50" damping="0.05" />
                    <geom name="distal2" size="0.028 0.08" pos="0 0 -0.08" type="capsule" material="self" />
                    <geom name="fingertip2" size="0.03 0.0155" pos="0 0 -0.1455" type="capsule" material="effector" />
                    <site name="touchtop2" pos="0.01 0 -0.17" />
                    <site name="touchbottom2" pos="-0.01 0 -0.17" />
                </body>
            </body>
        </body>

        <body name="k" pos="0.359374 0.305958 0.04">
            <geom name="pointmass" type="sphere" size=".04" material="self" mass="5000" condim="4"  group="2" solimp="0.9 0.95 0.001" solref="0.02 1"/>
            <joint name="root_x" type="slide"  pos="0 0 0" axis="1 0 0" damping="100" frictionloss="0"/>
            <joint name="root_y" type="slide"  pos="0 0 0" axis="0 1 0" damping="100" frictionloss="0"/>
        </body>
    </worldbody>

    <tendon>
        <fixed name="t1">
            <joint joint="root_x" coef="1"/>
            <joint joint="root_y" coef="0"/>
        </fixed>
        <fixed name="t2">
            <joint joint="root_x" coef="0"/>
            <joint joint="root_y" coef="1"/>
        </fixed>
    </tendon>

    <actuator>
        <general name="proximal" joint="proximal" />
        <general name="distal" joint="distal" gear="1.25 0 0 0 0 0" />
        <general name="distal2" joint="distal2" gear="1.5 0 0 0 0 0" />
    </actuator>
</mujoco>
