<mujoco model="franka_panda v200">
    <!-- =================================================
        Copyright 2018 Vikash Kumar
        Model   :: Franka (MuJoCoV2.0)
        Author  :: Vikash Kumar (vikashplus@gmail.com). Modified by Daniel Layeghi
        source  :: https://github.com/vikashplus/franka_sim
        License :: Under Apache License, Version 2.0 (the "License"); you may not use this file except in compliance with the License. You may obtain a copy of the License at http://www.apache.org/licenses/LICENSE-2.0 Unless required by applicable law or agreed to in writing, software distributed under the License is distributed on an "AS IS" BASIS, WITHOUT WARRANTIES OR CONDITIONS OF ANY KIND, either express or implied. See the License for the specific language governing permissions and limitations under the License.
    ====================================================== -->


    <include file="assets/basic_scene.xml"/>
    <include file="assets/assets.xml"/>
    <compiler meshdir=""/>

    <worldbody>
        <include file="assets/chain0.xml"/>
        <geom name="rail" pos="0.5 0 0.5" quat="0.5 0.5 0.5 -0.5" rgba="0.3 0.3 0.7 1" size="0.01 2.5" type="capsule"/>
        <body name="cart" pos="0 0 0">
            <joint axis="0 1 0" limited="false" margin="0.01" name="slider_cart_1" pos="0 0 0" range="-1 1" type="slide"/>
            <geom name="cart" pos="0.5 0.75 0.5" quat="0.5 0.5 0.5 -0.5"  size="0.05 0.05" type="capsule"/>
        </body>

        <body name="cart_2" pos="0 0 0">
            <joint axis="0 1 0 " limited="false" margin="0.01" name="slider_cart_2" pos="0 0 0" range="-1 1" type="slide"/>
            <geom name="cart_2" pos="0.5 0.5 0.5" quat="0.5 0.5 0.5 -0.5"  size="0.05 0.05" type="capsule"/>
        </body>
    </worldbody>

    <include file='assets/frc_actuator0.xml'/>

</mujoco>