<mujoco model="planar point mass">
    <compiler angle="radian" />
    <option timestep="0.01" cone="elliptic" iterations="200" />
    <size njmax="500" nconmax="100" />


   <default class="finger">
   <geom condim="4" solref="0.005 0.6" solimp="0 0.9 0.01 0.5 2" margin="0.001"/>
   <site size="0.025 0.03 0.025" group="3" type="ellipsoid" rgba="0.5 0.5 0.5 0.3"/>
   <general ctrllimited="true" ctrlrange="-1 1"/>
   </default>

    <worldbody>
        <geom name="ground" size="0.61 0.61 0.1" type="plane" />
        <geom name="wall_x" size="0.05 0.61 0.02" pos="-0.61 0 0.05" quat="0.707107 0 0.707107 0" type="plane" />
        <geom name="wall_y" size="0.61 0.05 0.02" pos="0 -0.61 0.05" quat="0.707107 -0.707107 0 0" type="plane" />
        <geom name="wall_neg_x" size="0.05 0.61 0.02" pos="0.61 0 0.05" quat="0.707107 0 -0.707107 0" type="plane" />
        <geom name="wall_neg_y" size="0.61 0.05 0.02" pos="0 0.61 0.05" quat="0.707107 0.707107 0 0" type="plane" />
        <camera name="fixed" pos="0 0 0.75" />
        <light name="light" pos="0 0 1" dir="0 0 -1" />
        <body pos="0 0 0.035" quat="0.707107 0.707107 0 0">
            <inertial pos="0 0 -0.0596966" mass="0.805178" diaginertia="0.00338471 0.00336697 0.000410748" />
            <joint name="proximal" pos="0 0 0" axis="0 -1 0" ref="-90" range="-150 -80" damping="0.05" />
            <geom name="proximal_decoration" size="0.034 0.033" quat="0.707107 0.707107 0 0" type="cylinder"/>
            <geom name="proximal" size="0.03 0.085" pos="0 0 -0.085" type="capsule"/>
            <body name="distal" childclass="finger" pos="0 0 -0.18">
                <inertial pos="0 0 -0.08" mass="0.463046" diaginertia="0.00145458 0.00145458 0.000181514" />
                <joint name="distal" pos="0 0 0" axis="0 -1 0" range="-50 50" damping="0.05" />
                <geom name="distal" size="0.028 0.08" pos="0 0 -0.08" type="capsule"/>
                <body name="distal2" childclass="finger" pos="0 0 -0.18">
                    <inertial pos="0 0 -0.097776" mass="0.635519" diaginertia="0.00208601 0.00208601 0.000259127" />
                    <joint name="distal2" pos="0 0 0" axis="0 -1 0" range="-50 50" damping="0.05" />
                    <geom name="distal2" size="0.028 0.08" pos="0 0 -0.08" type="capsule"/>
                    <geom name="fingertip2" size="0.03 0.0155" pos="0 0 -0.1455" type="capsule"/>
                    <site name="touchtop2" pos="0.01 0 -0.17" />
                    <site name="touchbottom2" pos="-0.01 0 -0.17" />
                </body>
            </body>
        </body>

        <geom name="target" pos="-0.350089 0.38106 0.04" type="sphere" rgba="0.5 1 0 0.25"  size=".04" contype="0" conaffinity="0"/>

    </worldbody>

    <actuator>
        <general name="proximal" joint="proximal" />
        <general name="distal" joint="distal" gear="1.25 0 0 0 0 0" />
        <general name="distal2" joint="distal2" gear="1.5 0 0 0 0 0" />
    </actuator>
</mujoco>
