<mujoco model="planar point mass">
    <compiler angle="radian" />
    <option timestep="0.01" cone="elliptic" iterations="200" />
    <size njmax="500" nconmax="100" />
    <visual>
        <quality shadowsize="2048" />
        <headlight ambient="0.4 0.4 0.4" diffuse="0.8 0.8 0.8" specular="0.1 0.1 0.1" />
    </visual>
    <default class="main">
        <geom solimp="0 0.9 0.01 0.5 2" />
        <general ctrllimited="true" ctrlrange="-1 1" />
    </default>
    <asset>
        <texture type="skybox" name="skybox" builtin="gradient" mark="random" rgb1="0.4 0.6 0.8" rgb2="0 0 0" markrgb="1 1 1" width="800" height="4800" />
        <texture type="2d" name="grid" builtin="checker" mark="edge" rgb1="0.1 0.2 0.3" rgb2="0.2 0.3 0.4" markrgb="0.2 0.3 0.4" width="300" height="300" />
        <material name="grid" texture="grid" texuniform="true" reflectance="0.2" />
        <material name="self" rgba="0.7 0.5 0.3 1" />
        <material name="self_default" rgba="0.7 0.5 0.3 1" />
        <material name="self_highlight" rgba="0 0.5 0.3 1" />
        <material name="effector" rgba="0.7 0.4 0.2 1" />
        <material name="effector_default" rgba="0.7 0.4 0.2 1" />
        <material name="effector_highlight" rgba="0 0.5 0.3 1" />
        <material name="decoration" rgba="0.3 0.5 0.7 1" />
        <material name="eye" rgba="0 0.2 1 1" />
        <material name="target" rgba="0.6 0.3 0.3 1" />
        <material name="target_default" rgba="0.6 0.3 0.3 1" />
        <material name="target_highlight" rgba="0.6 0.3 0.3 0.4" />
    </asset>
    <worldbody>
        <geom name="ground" size="0.35 0.35 0.1" type="plane" />
        <geom name="wall_x" size="0.02 0.3 0.02" pos="-0.35 0 0.02" quat="0.707107 0 0.707107 0" type="plane" />
        <geom name="wall_y" size="0.3 0.02 0.02" pos="0 -0.35 0.02" quat="0.707107 -0.707107 0 0" type="plane" />
        <geom name="wall_neg_x" size="0.02 0.3 0.02" pos="0.35 0 0.02" quat="0.707107 0 -0.707107 0" type="plane" />
        <geom name="wall_neg_y" size="0.3 0.02 0.02" pos="0 0.35 0.02" quat="0.707107 0.707107 0 0" type="plane" />
        <camera name="fixed" pos="0 0 0.75" />
        <light name="light" pos="0 0 1" dir="0 0 -1" />
        <body name="proximal" pos="0 0 0.02" quat="0.707107 0.707107 0 0">
            <inertial pos="0 0 -0.0291932" mass="0.0591876" diaginertia="7.61519e-05 7.40747e-05 6.21876e-06" />
            <joint name="proximal" pos="0 0 0" axis="0 -1 0" ref="-1.5708" range="-130 -60" damping="0.25" />
            <geom name="proximal_decoration" size="0.014 0.02" quat="0.707107 0.707107 0 0" type="cylinder" material="decoration" />
            <geom name="proximal" size="0.01 0.05" pos="0 0 -0.05" type="capsule" material="self" />
            <body name="distal" pos="0 0 -0.1">
                <inertial pos="0 0 -0.05" mass="0.0217147" diaginertia="2.14541e-05 2.14541e-05 6.9487e-07" />
                <joint name="distal" pos="0 0 0" axis="0 -1 0" range="-45 45" damping="0.3" />
                <geom name="distal" size="0.008 0.05" pos="0 0 -0.05" type="capsule" material="self" />
                <body name="distal2" pos="0.250351 0.104339 0.02">
                    <inertial pos="0 0 -0.05" mass="0.00522761" diaginertia="4.73273e-06 4.73273e-06 4.18209e-08" />
                    <joint name="distal2" pos="0 0 0" axis="0 -1 0" range="-45 45" damping="0.4" />
                    <geom name="distal2" size="0.004 0.05" pos="0 0 -0.05" type="capsule" material="self" />
                </body>
            </body>
        </body>
        <body name="k" pos="-0.246635 -0.000902295 0.02">
            <inertial pos="0 0 0" mass="0.0335103" diaginertia="5.36165e-06 5.36165e-06 5.36165e-06" />
            <geom size="0.02" rgba="1 0 0 1" />
        </body>
        <body name="a" pos="0.0987391 0.0208971 0.02">
            <inertial pos="0 0 0" mass="0.0335103" diaginertia="5.36165e-06 5.36165e-06 5.36165e-06" />
            <geom size="0.02" rgba="1 0 0 1" />
        </body>
        <body name="b" pos="-0.043384 0.15943 0.02">
            <inertial pos="0 0 0" mass="0.0335103" diaginertia="5.36165e-06 5.36165e-06 5.36165e-06" />
            <geom size="0.02" rgba="1 0 0 1" />
        </body>
        <body name="c" pos="0.276121 0.269426 0.02">
            <inertial pos="0 0 0" mass="0.0335103" diaginertia="5.36165e-06 5.36165e-06 5.36165e-06" />
            <geom size="0.02" rgba="1 0 0 1" />
        </body>
    </worldbody>
    <actuator>
        <general name="proximal" joint="proximal" gear="0.35 0 0 0 0 0" />
        <general name="distal" joint="distal" gear="0.5 0 0 0 0 0" />
        <general name="distal2" joint="distal2" gear="0.6 0 0 0 0 0" />
    </actuator>
</mujoco>
